Workbook

Sheet Income Statement
A1: Nestle India
A2: Income Statement of Last 3 FY
A3: Particulars | B3: FY 23-24 | C3: FY 25-26 | D3: FY 24-25
B4: Amt (in ₹ million) | C4: Amt (in ₹ million) | D4: Amt (in ₹ million)
A5: Revenue from operations | B5: 243938.9 | C5: 231546 | D5: 202015.6
A6: Other Income | B6: 1479.6 | C6: 403.5 | D6: 629.9
A7: A. Total Income | B7: =SUM(B5:B6) -> 245418.5 | C7: =SUM(C5:C6) -> 231949.5 | D7: =SUM(D5:D6) -> 202645.5
A9: Cost of Materials consumed | B9: 102168.8 | C9: 98140.4 | D9: 83901.5
A10: Purchase of Stock in trade | B10: 5373.7 | C10: 6954.8 | D10: 4993.1
A11: Changes in Inventories | B11: -456.8 | C11: -1682.3 | D11: -1396.6
A12: Employee benefit expense | B12: 23360.6 | C12: 21658.1 | D12: 20275.4
A13: Finance Costs | B13: 1454.9 | C13: 1583.1 | D13: 1360
A14: Depreciation and Amortisation | B14: 5677.5 | C14: 6992.3 | D14: 5399.2
A15: Other Expenses | B15: 54994.8 | C15: 53414.4 | D15: 46546.4
A16: B. Total Expenses | B16: =SUM(B9:B15) -> 192573.5 | C16: =SUM(C9:C15) -> 187060.8 | D16: =SUM(D9:D15) -> 161079
A18: C. PROFIT BEFORE SHARE OF (PROFIT) / LOSS OF AN ASSOCIATE, EXCEPTIONAL ITEMS AND TAX | B18: =B7-B16 -> 52845 | C18: =C7-C16 -> 44888.7 | D18: =D7-D16 -> 41566.5
A19: Share of (profit) / loss of associate accounted for using the equity method (net of tax) (C) | D19: 239.5
A20: Profit before Tax and Exceptional items | B20: =B18-B19 -> 52845 | C20: =C18-C19 -> 44888.7 | D20: =D18-D19 -> 41327
A21: Exceptional items [ Charge or (Credit)] | B21: -43.7 | C21: -1207.8 | D21: -2908.2
A22: Profit before Tax | B22: =B18-B21 -> 52888.7 | C22: =C18-C21 -> 46096.5 | D22: =D18-D21 -> 44474.7
A23: Tax Expense
A24: Current Tax | B24: 13156.8 | C24: 10312.8 | D24: 10951.8
A25: Deffered Tax | B25: 403.5 | C25: 337.7 | D25: 377.9
A27: Profit after tax | B27: =B22-(B24+B25) -> 39328.4 | C27: =C22-(C24+C25) -> 35446 | D27: =D22-(D24+D25) -> 33145

Sheet Balance Sheet
A1: Nestle India
A2: Balance Sheet of Last 3FY
A3: Particulars | B3: FY 23-24 | C3: FY 25-26 | D3: FY 24-25
B4: Amt (in ₹ million) | C4: Amt (in ₹ million) | D4: Amt (in ₹ million)
A5: Equity and Liabilities
A6: Equity Share Capital | B6: 964.2 | C6: 1928.3 | D6: 964.2
A7: Other Equity | B7: 32444.7 | C7: 49641.4 | D7: 39137.9
A8: Total Equity | B8: =SUM(B6:B7) -> 33408.9 | C8: =SUM(C6:C7) -> 51569.7 | D8: =SUM(D6:D7) -> 40102.1
A10: Non Current Liabilities
A11: Financial Liabilities
A12: Borrowings | B12: 254.8 | C12: 202.9 | D12: 224.8
A13: Lease Liabilities | B13: 2559.2 | C13: 3375.3 | D13: 3415.3
A14: Provisions | B14: 29172 | C14: 28236.1 | D14: 30901.5
A15: Deffered Tax Liabilities | B15: 120.4 | C15: 641.3 | D15: 299.6
A16: Other Non Current Liabilities | B16: 154.6 | C16: 187.3 | D16: 136.4
A17: Total Non Current Liabilities | B17: =SUM(B12:B16) -> 32261 | C17: =SUM(C12:C16) -> 32642.9 | D17: =SUM(D12:D16) -> 34977.6
A19: Current Liabilities
A20: Financial liabilities
A21: Borrowings | B21: 56.6 | C21: 41.5 | D21: 7308.6
A22: Lease Liabilities | B22: 574.7 | C22: 821.9 | D22: 719.8
A23: Trade Payables | B23: 22378.9 | C23: 29666.5 | D23: 23735.3
A24: Payables for Capex | B24: 5741.2 | C24: 1933.1 | D24: 2502.8
A25: Other Financial Liabilities | B25: 6417.2 | C25: 9787 | D25: 7553
A26: Other Current liabilities | B26: 1393.8 | C26: 1636.2 | D26: 2158.7
A27: Provisions | B27: 2616.2 | C27: 3077.9 | D27: 2422.8
A28: Current Tax Liabilities | B28: 382.1 | C28: 648.2 | D28: 452.5
A29: Total Current Liabilities | B29: =SUM(B21:B28) -> 39560.7 | C29: =SUM(C21:C28) -> 47612.3 | D29: =SUM(D21:D28) -> 46853.5
A30: Total Liabilities | B30: =SUM(B17+B29) -> 71821.7 | C30: =SUM(C17+C29) -> 80255.2 | D30: =SUM(D17+D29) -> 81831.1
A31: Total Equity and Liabilities | B31: =B8+B30 -> 105230.6 | C31: =C8+C30 -> 131824.9 | D31: =D8+D30 -> 121933.2
A33: Assets
A34: Non Current Assets
A35: Property, Plant & Equipment | B35: 30556.7 | C35: 57475.3 | D35: 49256.5
A36: Capital Work In Progress | B36: 17417.1 | C36: 5069.8 | D36: 11725.6
A37: Intagible Assets | B37: 4045.8 | C37: 5428.9 | D37: 5479.6
A38: Financial Assets
A39: Investment in Associates | B39: 4238.9 | C39: 5309.2 | D39: 5750.3
A40: Loans | B40: 80.1 | C40: 90.7 | D40: 80.9
A41: Other Financial Assets | B41: 565.1 | C41: 599.8 | D41: 554
A42: Other Non-Current Assets | B42: 13379.7 | C42: 11946.5 | D42: 11744.7
A43: Total Non Current Assets | B43: =SUM(B35:B42) -> 70283.4 | C43: =SUM(C35:C42) -> 85920.2 | D43: =SUM(D35:D42) -> 84591.6
...

Sheet Cash Flow Statement
A1: Nestle India
A2: Cash Flow Statement of 2 FY
A3: Particulars | B3: FY 24-25 | C3: FY 25-26
B4: Amt (₹ in million) | C4: Amt (₹ in million)
A5: A. Cash Flow from Operating Activities
A6: Profit before Tax | B6: ='Income Statement'!D22 -> 44474.7 | C6: ='Income Statement'!C22 -> 46096.5
A7: Add: Depreciation & Amortisation | B7: ='Income Statement'!D14 -> 5399.2 | C7: ='Income Statement'!C14 -> 6992.3
A8: Add: Finance Costs
A9: Interest on bank overdraft and others | B9: 80.3 | C9: 193.2
A10: Interest on lease liabilities | B10: 270.2 | C10: 301.9
A11: Unrealised exchange differences | B11: 48.2 | C11: 27.8
A12: Add/(Less): Loss / (profit) on property, plant and equipment sold/scrapped/ written off (net) | B12: -23.8 | C12: -39.9
A13: Less: Other Income
A14: Interest income | B14: -588.6 | C14: -354.6
A15: Allowance for impairment on financial assets | B15: -32.8 | C15: 41.4
A16: Add/(Less): Exceptional Items (Non Cash Portion) | B16: ='Income Statement'!D21 -> -2908.2 | C16: 0
A17: Operating Profit Before working Capital Changes | B17: =SUM(B6:B16) -> 46719.2 | C17: =SUM(C6:C16) -> 53258.6
A19: Changes in Working Capital
A20: Add/(less): Decrease / (increase) in inventories | B20: -7671 | C20: 2809.1
A21: Add/(less):Decrease / (increase) in trade receivables | B21: -700 | C21: 343.2
A22: Add/(less): Decrease / (increase) in other financial assets & other assets | B22: -1992.3 | C22: -729.9
A23: Add/ (Less): Increase / (decrease) in trade payables | B23: 1341.2 | C23: 5878.9
A24: Add/ (less): Increase / (decrease) in other financial liabilities & other liabilities | B24: 1926.3 | C24: 1697.6
A25: Add/(less): Increase / (decrease) in provision for contingencies | B25: 155.6 | C25: -2184.9
A26: Add/(less): Increase / (decrease) in provision for employee benefits | B26: -529.2 | C26: 115.5
A27: Cash generated from operations | B27: =SUM(B17:B26) -> 39249.8 | C27: =SUM(C17:C26) -> 61188.1
A28: Less: Income taxes paid (net of refunds) | B28: -9904.5 | C28: -10712.5
A29: Net cash flows generated from / (used in) operating activities | B29: =SUM(B27:B28) -> 29345.3 | C29: =SUM(C27:C28) -> 50475.6
A31: B. CASH FLOWS FROM INVESTING ACTIVITIES
A32: Purchase of property, plant and equipment including capital work-in-progress | B32: -20086.4 | C32: -8297
A33: Proceeds from sale of property, plant and equipment | B33: 42.5 | C33: 34.5
A34: (Purchase of) / proceeds from sale of Mutual funds (net) | B34: 0 | C34: 0
A35: Proceeds from redemption of tax free bonds and other investments | B35: 4238.9 | C35: 0
A36: Investment in equity shares of associate | B36: -7056 | C36: 0
A37: Proceeds from sale of businesses net of tax | B37: 2664.7 | C37: 0
A38: Amount received from insurance pension plan - separations | B38: 1325.8 | C38: 1701.1
A39: Net decrease / (increase) in loans to employees | B39: 6.2 | C39: -16.8
A40: Interest received on bank deposits, investments, tax free bonds, employee loans etc. | B40: 755.3 | C40: 341.4
A41: Net cash generated from / (used in) investing activities | B41: =SUM(B32:B40) -> -18109 | C41: =SUM(C32:C40) -> -6236.8
A43: C. CASH FLOWS FROM FINANCING ACTIVITIES
...
